[TOC]

# 一、关于异步编程

## 1.同步与异步

同步就是顺序地执行，异步是一种事件驱动编程，可以继续执行其他任务，之后完成之后通知调用者

## 2.实现异步的几种方式

* 多线程，同时开启多个线程，不同操作能**并行**执行
* js单线程，
* 并行与并发，并发指的是：**某一时间段，多任务同时进行，某一时刻，只有某一个任务执行**

**并发连接数：每秒种服务器建立的总连接数，**

## 并发模型

事件循环eventloop流程：

* 宿主环境为js创建线程，创建堆和栈，堆内存储js对象，栈内存执行上下文
* 栈内为同步任务执行，执行完即退栈，异步任务执行时，进入等待状态，不入栈，向消息队列中插入改事件消息
* 栈内同步任务执行之后，线程从消息队列中取出事件消息，异步任务入栈，执行回调函数，如果未绑定回调，这个消息会被丢弃，执行完任务后退栈。
* 线程空闲时，继续拉去消息队列的下一轮消息（next tick）

## async／await优点

* try catch进行异常处理
* 调试时可以给每个异步加断点



## macro task和micro task

* macro task ：整体代码，setTimeout、setInterval、setImmediate、I/O、UI、rendering
* micro-task：process.nextTick promise 

# 二、异步常规方法

## 1.回调函数

回调地狱，

## 信任问题

回调嵌套，多次调用传入的回调，可能传回错误的数据。

这样的嵌套，控制权在第三方，对于回调函数的调用方式、时间、次数、顺序，回调函数参数，还有下一节将要介绍的异常和错误都是不可控的

## 顺序性

由于异步的非顺序性，如果出问题，跟踪异步流，找出问题所在，跟踪这类异步流，非常困难。

## 错误处理

异步的错误try catch不到

# 三、回调与promise

### 1.promise实现

### promise 的缺点

* 无法取消promise 一旦新建就会执行
* 不设置promise回调函数，promise内部的错误不会反映到外部
* 处于pending状态时，无法得知目前进展到哪一个阶段，没有进度条

# 四、async／await

## 1. 基本规则

* await表示在这里等待promise返回结果，
* 获得返回值，await等待的虽然是promise对象，但是不需要写.then(),可以直接得到返回值
* 错误捕捉，可以使用try catch语法捕捉错误

## async／await是generator／yield的语法糖

```
function* main() {
    const result1 = yield timeOut(200)
    console.log(result1)
    const result2 = yield timeOut(result1)
    console.log(result2)
    const result3 = yield timeOut(result2)
    console.log(result3)
}
```

yield执行后面的函数，将函数的返回值返回给yield执行处

```
function* main() {
    const result1 = yield timeOut(200)
    console.log(result1)
    const result2 = yield timeOut(result1)
    console.log(result2)
    const result3 = yield timeOut(result2)
    console.log(result3)
}
```

生成器的目的：yield后面的表达式被执行，返回值返回给了yield执行处

```
yield后面的表达式被执行，表达式的返回值被返回给了yield执行处，

function step(generator) {
  const gen = generator()
  
  //由于其传值，返回步骤交错的特性，记录上一次yield 传过来的值，
  let lastValue
  //包裹为promise，并执行表达式
  return ()=>Promise.resolve(gen.next(lastValue).value).then(value => {
    lastValue = value
    return lastValue
  })
}

利用生成器，模拟出await的效果
const run = step(main) 

//返回的是promise.resolve(当前函数第一个yield执行之后的所得值).then（修改value，返回执行结束的值传递给下一个next）执行这个表达式并且将其包装为一个带有执行结果的一个promise 返回此promise

function recursive(promise) {
    promise.then(result => {
        if (result) {
            recursive(promise)
        }
    })
}

recursive(run)
```

# 三、异常处理

## 1.promise

* 未捕获的reject会一直传递到末尾，通过catch接住
* 抛出的异常也会被catch接住

```
function fetch(callback) {
    return new Promise((resolve, reject) => {
        throw Error('用户不存在')
    })
}

fetch().then(result => {
    console.log('请求处理', result) // 永远不会执行
}).catch(error => {
    console.log('请求处理异常', error) // 请求处理异常 用户不存在
})
```

```
const promiseF = new Promise((resolve, reject) => {
    resolve('ok')
})
promiseF.then(result => {
    return Promise.reject('error1')
}).then(result => {
    console.log(result) // 永远不会执行
    return Promise.resolve('ok1') // 永远不会执行
}).then(result => {
    console.log(result) // 永远不会执行
}).catch(error => {
    console.log(error) // error1
})
```

也就说，前面的异常被catch之后，后面的会继续执行，如果函数抛出错误或返回一个reject的promise，则调用将返回一个reject的promise

```
Promise.resolve()
  .then( () => {
    // 使 .then() 返回一个 rejected promise
    throw 'Oh no!';
  })
  .then( () => {
    console.log( 'Not called.' );
  }, reason => {
    console.error( 'onRejected function called: ', reason );
});
```

一个resolving promise会被返回，下面第一个then回返回一个用resolving promise包装的42，**即使前面的promise 是rejected的**

```
Promise.reject()
  .then( () => 99, () => 42 ) // onRejected returns 42 which is wrapped in a resolving Promise
  .then( solution => console.log( 'Resolved with ' + solution ) ); // Resolved with 42
```

* promise中无法捕获的异常

永远不要在macrotask中抛出异常，因为macrotask队列会脱离现在执行的上下文，throw之后无法调用then catch方法，异常无法被当前环境捕获（对应的setTimeout会自动绑定window   this）

修改为reject，

```
function fetch(callback) {
    return new Promise((resolve, reject) => {
        setTimeout(() => {
             throw Error('用户不存在')
        })
    })
}
fetch().then(result => {
    console.log('请求处理', result) // 永远不会执行
}).catch(error => {
    console.log('请求处理异常', error) // 永远不会执行
})
```